[2024-05-16 12:37:36,072][flwr][INFO] - Starting Flower simulation, config: ServerConfig(num_rounds=3, round_timeout=None)
[2024-05-16 12:37:38,323][flwr][INFO] - Flower VCE: Ray initialized with resources: {'node:172.16.0.2': 1.0, 'memory': 7266530919.0, 'object_store_memory': 3633265459.0, 'CPU': 16.0}
[2024-05-16 12:37:38,323][flwr][INFO] - Initializing global parameters
[2024-05-16 12:37:38,323][flwr][INFO] - Requesting initial parameters from one random client
[2024-05-16 12:37:39,335][flwr][INFO] - Received initial parameters from one random client
[2024-05-16 12:37:39,336][flwr][INFO] - Evaluating initial parameters
[2024-05-16 12:37:40,009][flwr][INFO] - initial parameters (loss, other metrics): 721.4820699691772, {'accuracy': 0.0869}
[2024-05-16 12:37:40,009][flwr][INFO] - FL starting
[2024-05-16 12:37:40,009][flwr][DEBUG] - fit_round 1: strategy sampled 1 clients (out of 3)
[2024-05-16 12:37:40,098][flwr][ERROR] - [36mray::launch_and_fit()[39m (pid=29878, ip=172.16.0.2)
  File "/home/ishmam/anaconda3/envs/fl/lib/python3.8/site-packages/flwr/simulation/ray_transport/ray_client_proxy.py", line 148, in launch_and_fit
    return maybe_call_fit(
  File "/home/ishmam/anaconda3/envs/fl/lib/python3.8/site-packages/flwr/client/client.py", line 184, in maybe_call_fit
    return client.fit(fit_ins)
  File "/home/ishmam/anaconda3/envs/fl/lib/python3.8/site-packages/flwr/client/app.py", line 297, in _fit
    results = self.numpy_client.fit(parameters, ins.config)  # type: ignore
  File "/home/ishmam/Documents/Research/Federated Learning/TestFL/client.py", line 42, in fit
    train(self.model, self.train_loader, optim, epochs, self.device)
  File "/home/ishmam/Documents/Research/Federated Learning/TestFL/model.py", line 38, in train
    print(f"Epoch {epoch} / {len(epochs)}:\n")
TypeError: object of type 'int' has no len()
[2024-05-16 12:37:40,098][flwr][DEBUG] - fit_round 1 received 0 results and 1 failures
[2024-05-16 12:37:40,742][flwr][INFO] - fit progress: (1, 721.4820699691772, {'accuracy': 0.0869}, 0.7332669569987047)
[2024-05-16 12:37:40,742][flwr][DEBUG] - evaluate_round 1: strategy sampled 2 clients (out of 3)
[2024-05-16 12:37:40,846][flwr][ERROR] - [36mray::launch_and_evaluate()[39m (pid=29878, ip=172.16.0.2)
  File "/home/ishmam/anaconda3/envs/fl/lib/python3.8/site-packages/flwr/simulation/ray_transport/ray_client_proxy.py", line 160, in launch_and_evaluate
    return maybe_call_evaluate(
  File "/home/ishmam/anaconda3/envs/fl/lib/python3.8/site-packages/flwr/client/client.py", line 205, in maybe_call_evaluate
    return client.evaluate(evaluate_ins)
  File "/home/ishmam/anaconda3/envs/fl/lib/python3.8/site-packages/flwr/client/app.py", line 321, in _evaluate
    results = self.numpy_client.evaluate(parameters, ins.config)  # type: ignore
TypeError: evaluate() takes 2 positional arguments but 3 were given
[2024-05-16 12:37:41,781][flwr][ERROR] - [36mray::launch_and_evaluate()[39m (pid=29885, ip=172.16.0.2)
  File "/home/ishmam/anaconda3/envs/fl/lib/python3.8/site-packages/flwr/simulation/ray_transport/ray_client_proxy.py", line 160, in launch_and_evaluate
    return maybe_call_evaluate(
  File "/home/ishmam/anaconda3/envs/fl/lib/python3.8/site-packages/flwr/client/client.py", line 205, in maybe_call_evaluate
    return client.evaluate(evaluate_ins)
  File "/home/ishmam/anaconda3/envs/fl/lib/python3.8/site-packages/flwr/client/app.py", line 321, in _evaluate
    results = self.numpy_client.evaluate(parameters, ins.config)  # type: ignore
TypeError: evaluate() takes 2 positional arguments but 3 were given
[2024-05-16 12:37:41,782][flwr][DEBUG] - evaluate_round 1 received 0 results and 2 failures
[2024-05-16 12:37:41,782][flwr][DEBUG] - fit_round 2: strategy sampled 1 clients (out of 3)
[2024-05-16 12:37:41,853][flwr][ERROR] - [36mray::launch_and_fit()[39m (pid=29885, ip=172.16.0.2)
  File "/home/ishmam/anaconda3/envs/fl/lib/python3.8/site-packages/flwr/simulation/ray_transport/ray_client_proxy.py", line 148, in launch_and_fit
    return maybe_call_fit(
  File "/home/ishmam/anaconda3/envs/fl/lib/python3.8/site-packages/flwr/client/client.py", line 184, in maybe_call_fit
    return client.fit(fit_ins)
  File "/home/ishmam/anaconda3/envs/fl/lib/python3.8/site-packages/flwr/client/app.py", line 297, in _fit
    results = self.numpy_client.fit(parameters, ins.config)  # type: ignore
  File "/home/ishmam/Documents/Research/Federated Learning/TestFL/client.py", line 42, in fit
    train(self.model, self.train_loader, optim, epochs, self.device)
  File "/home/ishmam/Documents/Research/Federated Learning/TestFL/model.py", line 38, in train
    print(f"Epoch {epoch} / {len(epochs)}:\n")
TypeError: object of type 'int' has no len()
[2024-05-16 12:37:41,853][flwr][DEBUG] - fit_round 2 received 0 results and 1 failures
[2024-05-16 12:37:42,501][flwr][INFO] - fit progress: (2, 721.4820699691772, {'accuracy': 0.0869}, 2.492474927999865)
[2024-05-16 12:37:42,502][flwr][DEBUG] - evaluate_round 2: strategy sampled 2 clients (out of 3)
[2024-05-16 12:37:42,623][flwr][ERROR] - [36mray::launch_and_evaluate()[39m (pid=29885, ip=172.16.0.2)
  File "/home/ishmam/anaconda3/envs/fl/lib/python3.8/site-packages/flwr/simulation/ray_transport/ray_client_proxy.py", line 160, in launch_and_evaluate
    return maybe_call_evaluate(
  File "/home/ishmam/anaconda3/envs/fl/lib/python3.8/site-packages/flwr/client/client.py", line 205, in maybe_call_evaluate
    return client.evaluate(evaluate_ins)
  File "/home/ishmam/anaconda3/envs/fl/lib/python3.8/site-packages/flwr/client/app.py", line 321, in _evaluate
    results = self.numpy_client.evaluate(parameters, ins.config)  # type: ignore
TypeError: evaluate() takes 2 positional arguments but 3 were given
[2024-05-16 12:37:42,624][flwr][ERROR] - [36mray::launch_and_evaluate()[39m (pid=29878, ip=172.16.0.2)
  File "/home/ishmam/anaconda3/envs/fl/lib/python3.8/site-packages/flwr/simulation/ray_transport/ray_client_proxy.py", line 160, in launch_and_evaluate
    return maybe_call_evaluate(
  File "/home/ishmam/anaconda3/envs/fl/lib/python3.8/site-packages/flwr/client/client.py", line 205, in maybe_call_evaluate
    return client.evaluate(evaluate_ins)
  File "/home/ishmam/anaconda3/envs/fl/lib/python3.8/site-packages/flwr/client/app.py", line 321, in _evaluate
    results = self.numpy_client.evaluate(parameters, ins.config)  # type: ignore
TypeError: evaluate() takes 2 positional arguments but 3 were given
[2024-05-16 12:37:42,624][flwr][DEBUG] - evaluate_round 2 received 0 results and 2 failures
[2024-05-16 12:37:42,624][flwr][DEBUG] - fit_round 3: strategy sampled 1 clients (out of 3)
[2024-05-16 12:37:42,708][flwr][ERROR] - [36mray::launch_and_fit()[39m (pid=29878, ip=172.16.0.2)
  File "/home/ishmam/anaconda3/envs/fl/lib/python3.8/site-packages/flwr/simulation/ray_transport/ray_client_proxy.py", line 148, in launch_and_fit
    return maybe_call_fit(
  File "/home/ishmam/anaconda3/envs/fl/lib/python3.8/site-packages/flwr/client/client.py", line 184, in maybe_call_fit
    return client.fit(fit_ins)
  File "/home/ishmam/anaconda3/envs/fl/lib/python3.8/site-packages/flwr/client/app.py", line 297, in _fit
    results = self.numpy_client.fit(parameters, ins.config)  # type: ignore
  File "/home/ishmam/Documents/Research/Federated Learning/TestFL/client.py", line 42, in fit
    train(self.model, self.train_loader, optim, epochs, self.device)
  File "/home/ishmam/Documents/Research/Federated Learning/TestFL/model.py", line 38, in train
    print(f"Epoch {epoch} / {len(epochs)}:\n")
TypeError: object of type 'int' has no len()
[2024-05-16 12:37:42,708][flwr][DEBUG] - fit_round 3 received 0 results and 1 failures
[2024-05-16 12:37:43,339][flwr][INFO] - fit progress: (3, 721.4820699691772, {'accuracy': 0.0869}, 3.3297592119997717)
[2024-05-16 12:37:43,339][flwr][DEBUG] - evaluate_round 3: strategy sampled 2 clients (out of 3)
[2024-05-16 12:37:43,447][flwr][ERROR] - [36mray::launch_and_evaluate()[39m (pid=29878, ip=172.16.0.2)
  File "/home/ishmam/anaconda3/envs/fl/lib/python3.8/site-packages/flwr/simulation/ray_transport/ray_client_proxy.py", line 160, in launch_and_evaluate
    return maybe_call_evaluate(
  File "/home/ishmam/anaconda3/envs/fl/lib/python3.8/site-packages/flwr/client/client.py", line 205, in maybe_call_evaluate
    return client.evaluate(evaluate_ins)
  File "/home/ishmam/anaconda3/envs/fl/lib/python3.8/site-packages/flwr/client/app.py", line 321, in _evaluate
    results = self.numpy_client.evaluate(parameters, ins.config)  # type: ignore
TypeError: evaluate() takes 2 positional arguments but 3 were given
[2024-05-16 12:37:43,448][flwr][ERROR] - [36mray::launch_and_evaluate()[39m (pid=29885, ip=172.16.0.2)
  File "/home/ishmam/anaconda3/envs/fl/lib/python3.8/site-packages/flwr/simulation/ray_transport/ray_client_proxy.py", line 160, in launch_and_evaluate
    return maybe_call_evaluate(
  File "/home/ishmam/anaconda3/envs/fl/lib/python3.8/site-packages/flwr/client/client.py", line 205, in maybe_call_evaluate
    return client.evaluate(evaluate_ins)
  File "/home/ishmam/anaconda3/envs/fl/lib/python3.8/site-packages/flwr/client/app.py", line 321, in _evaluate
    results = self.numpy_client.evaluate(parameters, ins.config)  # type: ignore
TypeError: evaluate() takes 2 positional arguments but 3 were given
[2024-05-16 12:37:43,449][flwr][DEBUG] - evaluate_round 3 received 0 results and 2 failures
[2024-05-16 12:37:43,449][flwr][INFO] - FL finished in 3.4399052979988483
[2024-05-16 12:37:43,449][flwr][INFO] - app_fit: losses_distributed []
[2024-05-16 12:37:43,449][flwr][INFO] - app_fit: metrics_distributed_fit {}
[2024-05-16 12:37:43,449][flwr][INFO] - app_fit: metrics_distributed {}
[2024-05-16 12:37:43,449][flwr][INFO] - app_fit: losses_centralized [(0, 721.4820699691772), (1, 721.4820699691772), (2, 721.4820699691772), (3, 721.4820699691772)]
[2024-05-16 12:37:43,449][flwr][INFO] - app_fit: metrics_centralized {'accuracy': [(0, 0.0869), (1, 0.0869), (2, 0.0869), (3, 0.0869)]}
