[2024-05-16 12:34:08,811][flwr][INFO] - Starting Flower simulation, config: ServerConfig(num_rounds=3, round_timeout=None)
[2024-05-16 12:34:11,019][flwr][INFO] - Flower VCE: Ray initialized with resources: {'memory': 7030559540.0, 'object_store_memory': 3515279769.0, 'node:172.16.0.2': 1.0, 'CPU': 16.0}
[2024-05-16 12:34:11,019][flwr][INFO] - Initializing global parameters
[2024-05-16 12:34:11,019][flwr][INFO] - Requesting initial parameters from one random client
[2024-05-16 12:34:12,022][flwr][INFO] - Received initial parameters from one random client
[2024-05-16 12:34:12,022][flwr][INFO] - Evaluating initial parameters
[2024-05-16 12:34:12,667][flwr][INFO] - initial parameters (loss, other metrics): 720.7170560359955, {'accuracy': 0.1039}
[2024-05-16 12:34:12,667][flwr][INFO] - FL starting
[2024-05-16 12:34:12,667][flwr][DEBUG] - fit_round 1: strategy sampled 1 clients (out of 3)
[2024-05-16 12:34:12,757][flwr][ERROR] - [36mray::launch_and_fit()[39m (pid=28768, ip=172.16.0.2)
  File "/home/ishmam/anaconda3/envs/fl/lib/python3.8/site-packages/flwr/simulation/ray_transport/ray_client_proxy.py", line 148, in launch_and_fit
    return maybe_call_fit(
  File "/home/ishmam/anaconda3/envs/fl/lib/python3.8/site-packages/flwr/client/client.py", line 184, in maybe_call_fit
    return client.fit(fit_ins)
  File "/home/ishmam/anaconda3/envs/fl/lib/python3.8/site-packages/flwr/client/app.py", line 297, in _fit
    results = self.numpy_client.fit(parameters, ins.config)  # type: ignore
  File "/home/ishmam/Documents/Research/Federated Learning/TestFL/client.py", line 38, in fit
    epochs = cfg["local_epochs"]
KeyError: 'local_epochs'
[2024-05-16 12:34:12,757][flwr][DEBUG] - fit_round 1 received 0 results and 1 failures
[2024-05-16 12:34:13,403][flwr][INFO] - fit progress: (1, 720.7170560359955, {'accuracy': 0.1039}, 0.735880869000539)
[2024-05-16 12:34:13,403][flwr][DEBUG] - evaluate_round 1: strategy sampled 2 clients (out of 3)
[2024-05-16 12:34:13,505][flwr][ERROR] - [36mray::launch_and_evaluate()[39m (pid=28768, ip=172.16.0.2)
  File "/home/ishmam/anaconda3/envs/fl/lib/python3.8/site-packages/flwr/simulation/ray_transport/ray_client_proxy.py", line 160, in launch_and_evaluate
    return maybe_call_evaluate(
  File "/home/ishmam/anaconda3/envs/fl/lib/python3.8/site-packages/flwr/client/client.py", line 205, in maybe_call_evaluate
    return client.evaluate(evaluate_ins)
  File "/home/ishmam/anaconda3/envs/fl/lib/python3.8/site-packages/flwr/client/app.py", line 321, in _evaluate
    results = self.numpy_client.evaluate(parameters, ins.config)  # type: ignore
TypeError: evaluate() takes 2 positional arguments but 3 were given
[2024-05-16 12:34:14,476][flwr][ERROR] - [36mray::launch_and_evaluate()[39m (pid=28770, ip=172.16.0.2)
  File "/home/ishmam/anaconda3/envs/fl/lib/python3.8/site-packages/flwr/simulation/ray_transport/ray_client_proxy.py", line 160, in launch_and_evaluate
    return maybe_call_evaluate(
  File "/home/ishmam/anaconda3/envs/fl/lib/python3.8/site-packages/flwr/client/client.py", line 205, in maybe_call_evaluate
    return client.evaluate(evaluate_ins)
  File "/home/ishmam/anaconda3/envs/fl/lib/python3.8/site-packages/flwr/client/app.py", line 321, in _evaluate
    results = self.numpy_client.evaluate(parameters, ins.config)  # type: ignore
TypeError: evaluate() takes 2 positional arguments but 3 were given
[2024-05-16 12:34:14,477][flwr][DEBUG] - evaluate_round 1 received 0 results and 2 failures
[2024-05-16 12:34:14,477][flwr][DEBUG] - fit_round 2: strategy sampled 1 clients (out of 3)
[2024-05-16 12:34:14,558][flwr][ERROR] - [36mray::launch_and_fit()[39m (pid=28770, ip=172.16.0.2)
  File "/home/ishmam/anaconda3/envs/fl/lib/python3.8/site-packages/flwr/simulation/ray_transport/ray_client_proxy.py", line 148, in launch_and_fit
    return maybe_call_fit(
  File "/home/ishmam/anaconda3/envs/fl/lib/python3.8/site-packages/flwr/client/client.py", line 184, in maybe_call_fit
    return client.fit(fit_ins)
  File "/home/ishmam/anaconda3/envs/fl/lib/python3.8/site-packages/flwr/client/app.py", line 297, in _fit
    results = self.numpy_client.fit(parameters, ins.config)  # type: ignore
  File "/home/ishmam/Documents/Research/Federated Learning/TestFL/client.py", line 38, in fit
    epochs = cfg["local_epochs"]
KeyError: 'local_epochs'
[2024-05-16 12:34:14,558][flwr][DEBUG] - fit_round 2 received 0 results and 1 failures
[2024-05-16 12:34:15,340][flwr][INFO] - fit progress: (2, 720.7170560359955, {'accuracy': 0.1039}, 2.6731686839993927)
[2024-05-16 12:34:15,340][flwr][DEBUG] - evaluate_round 2: strategy sampled 2 clients (out of 3)
[2024-05-16 12:34:15,461][flwr][ERROR] - [36mray::launch_and_evaluate()[39m (pid=28770, ip=172.16.0.2)
  File "/home/ishmam/anaconda3/envs/fl/lib/python3.8/site-packages/flwr/simulation/ray_transport/ray_client_proxy.py", line 160, in launch_and_evaluate
    return maybe_call_evaluate(
  File "/home/ishmam/anaconda3/envs/fl/lib/python3.8/site-packages/flwr/client/client.py", line 205, in maybe_call_evaluate
    return client.evaluate(evaluate_ins)
  File "/home/ishmam/anaconda3/envs/fl/lib/python3.8/site-packages/flwr/client/app.py", line 321, in _evaluate
    results = self.numpy_client.evaluate(parameters, ins.config)  # type: ignore
TypeError: evaluate() takes 2 positional arguments but 3 were given
[2024-05-16 12:34:15,462][flwr][ERROR] - [36mray::launch_and_evaluate()[39m (pid=28768, ip=172.16.0.2)
  File "/home/ishmam/anaconda3/envs/fl/lib/python3.8/site-packages/flwr/simulation/ray_transport/ray_client_proxy.py", line 160, in launch_and_evaluate
    return maybe_call_evaluate(
  File "/home/ishmam/anaconda3/envs/fl/lib/python3.8/site-packages/flwr/client/client.py", line 205, in maybe_call_evaluate
    return client.evaluate(evaluate_ins)
  File "/home/ishmam/anaconda3/envs/fl/lib/python3.8/site-packages/flwr/client/app.py", line 321, in _evaluate
    results = self.numpy_client.evaluate(parameters, ins.config)  # type: ignore
TypeError: evaluate() takes 2 positional arguments but 3 were given
[2024-05-16 12:34:15,463][flwr][DEBUG] - evaluate_round 2 received 0 results and 2 failures
[2024-05-16 12:34:15,463][flwr][DEBUG] - fit_round 3: strategy sampled 1 clients (out of 3)
[2024-05-16 12:34:15,546][flwr][ERROR] - [36mray::launch_and_fit()[39m (pid=28768, ip=172.16.0.2)
  File "/home/ishmam/anaconda3/envs/fl/lib/python3.8/site-packages/flwr/simulation/ray_transport/ray_client_proxy.py", line 148, in launch_and_fit
    return maybe_call_fit(
  File "/home/ishmam/anaconda3/envs/fl/lib/python3.8/site-packages/flwr/client/client.py", line 184, in maybe_call_fit
    return client.fit(fit_ins)
  File "/home/ishmam/anaconda3/envs/fl/lib/python3.8/site-packages/flwr/client/app.py", line 297, in _fit
    results = self.numpy_client.fit(parameters, ins.config)  # type: ignore
  File "/home/ishmam/Documents/Research/Federated Learning/TestFL/client.py", line 38, in fit
    epochs = cfg["local_epochs"]
KeyError: 'local_epochs'
[2024-05-16 12:34:15,546][flwr][DEBUG] - fit_round 3 received 0 results and 1 failures
[2024-05-16 12:34:16,175][flwr][INFO] - fit progress: (3, 720.7170560359955, {'accuracy': 0.1039}, 3.5078372309999395)
[2024-05-16 12:34:16,175][flwr][DEBUG] - evaluate_round 3: strategy sampled 2 clients (out of 3)
[2024-05-16 12:34:16,282][flwr][ERROR] - [36mray::launch_and_evaluate()[39m (pid=28768, ip=172.16.0.2)
  File "/home/ishmam/anaconda3/envs/fl/lib/python3.8/site-packages/flwr/simulation/ray_transport/ray_client_proxy.py", line 160, in launch_and_evaluate
    return maybe_call_evaluate(
  File "/home/ishmam/anaconda3/envs/fl/lib/python3.8/site-packages/flwr/client/client.py", line 205, in maybe_call_evaluate
    return client.evaluate(evaluate_ins)
  File "/home/ishmam/anaconda3/envs/fl/lib/python3.8/site-packages/flwr/client/app.py", line 321, in _evaluate
    results = self.numpy_client.evaluate(parameters, ins.config)  # type: ignore
TypeError: evaluate() takes 2 positional arguments but 3 were given
[2024-05-16 12:34:16,283][flwr][ERROR] - [36mray::launch_and_evaluate()[39m (pid=28770, ip=172.16.0.2)
  File "/home/ishmam/anaconda3/envs/fl/lib/python3.8/site-packages/flwr/simulation/ray_transport/ray_client_proxy.py", line 160, in launch_and_evaluate
    return maybe_call_evaluate(
  File "/home/ishmam/anaconda3/envs/fl/lib/python3.8/site-packages/flwr/client/client.py", line 205, in maybe_call_evaluate
    return client.evaluate(evaluate_ins)
  File "/home/ishmam/anaconda3/envs/fl/lib/python3.8/site-packages/flwr/client/app.py", line 321, in _evaluate
    results = self.numpy_client.evaluate(parameters, ins.config)  # type: ignore
TypeError: evaluate() takes 2 positional arguments but 3 were given
[2024-05-16 12:34:16,283][flwr][DEBUG] - evaluate_round 3 received 0 results and 2 failures
[2024-05-16 12:34:16,283][flwr][INFO] - FL finished in 3.6164231570000993
[2024-05-16 12:34:16,284][flwr][INFO] - app_fit: losses_distributed []
[2024-05-16 12:34:16,284][flwr][INFO] - app_fit: metrics_distributed_fit {}
[2024-05-16 12:34:16,284][flwr][INFO] - app_fit: metrics_distributed {}
[2024-05-16 12:34:16,284][flwr][INFO] - app_fit: losses_centralized [(0, 720.7170560359955), (1, 720.7170560359955), (2, 720.7170560359955), (3, 720.7170560359955)]
[2024-05-16 12:34:16,284][flwr][INFO] - app_fit: metrics_centralized {'accuracy': [(0, 0.1039), (1, 0.1039), (2, 0.1039), (3, 0.1039)]}
